<?xml version="1.0"?>
<robot xmlns:xacro="http://www.ros.org/wiki/xacro"  name="mobo_bot">


    <xacro:include filename="$(find mobo_bot_description)/urdf/color_materials.xacro"/>
    <xacro:include filename="$(find mobo_bot_description)/urdf/part_macros.xacro"/>
    <xacro:include filename="$(find mobo_bot_description)/urdf/inertia_macros.xacro"/>


    <xacro:property name="use_ros2_control" value="false"/>


    <xacro:property name="base_chassis_height" value="0.1"/>


    <xacro:arg name="laser_visual" default="false"/>
    <xacro:arg name="imu_visual"   default="true"/>
    <xacro:arg name="sonar_visual"   default="false"/>
    <xacro:arg name="cam_visual"   default="true"/>

    



    <!-- BASE LINK -->

    <!-- <base joint/> -->
    <link name="base_link">  
    </link>

    <!-- ################# -->













    <!-- CHASSIS LINK -->

    <joint name="base_chassis_joint" type="fixed">
        <parent link="base_link"/>
        <child link="base_chassis_link"/>
        <origin xyz="0 0 0.05"/>
    </joint>


    <link name="base_chassis_link">
        <xacro:box_with_fillet size_x="0.4" size_y="0.30" size_z="${base_chassis_height}" fr="0.1" material="white" x="-0.06" y="0" z="${base_chassis_height/2}"/>
        <collision>
           <origin xyz="-0.06 0 ${base_chassis_height/2}" rpy="0 0 0"/>
            <geometry>
                <box size="0.4 0.29 ${base_chassis_height}"/>
            </geometry>
        </collision>
        <xacro:inertial_box mass="5.0" x="0.4" y="0.30" z="${base_chassis_height}">
            <origin xyz="-0.06 0 ${base_chassis_height/2}" rpy="0 0 0"/>
        </xacro:inertial_box>
    </link>
    <gazebo reference="base_chassis_link">
        <material>Gazebo/White</material>
    </gazebo>
    <!--  ########################### -->























    <!--  FRONT LEFT WHEEL LINK -->

    <joint name="left_wheel_joint" type="continuous">
        <parent link="base_chassis_link"/>
        <child link="left_wheel_link"/>
        <origin xyz="0 0.17 0" rpy="${-pi/2} 0 0"/>
        <axis xyz="0 0 1"/>
    </joint>


    <link name="left_wheel_link">
        <visual>
            <origin xyz="0 0 0" rpy="0 0 0"/>
            <geometry>
                <cylinder radius="0.05" length="0.04"/>
            </geometry>
            <material name="black"/>
        </visual>
        <collision>
           <origin xyz="0 0 0" rpy="0 0 0"/>
            <geometry>
                <sphere radius="0.05" />
            </geometry>
        </collision>
        <xacro:inertial_cylinder mass="0.5" length="0.04" radius="0.05">
            <origin xyz="0 0 0" rpy="0 0 0"/>
        </xacro:inertial_cylinder>
    </link>

    <gazebo reference="left_wheel_link">
        <mu1>1.0</mu1>
        <mu2>1.0</mu2>
        <!-- <kp>1000000.0</kp>
        <kd>1.0</kd>
        <fdir1>1 0 0</fdir1>
        <minDepth>0.1</minDepth> -->
        <material>Gazebo/FlatBlack</material>
    </gazebo>


    <joint name="left_wheel_rim_joint" type="fixed">
        <parent link="left_wheel_link"/>
        <child link="left_wheel_rim_link"/>
        <origin xyz="0 0 0" rpy="0 0 0"/>
    </joint>

    <link name="left_wheel_rim_link">
        <visual>
            <origin xyz="0 0 0" rpy="0 0 0"/>
            <geometry>
                <box size="0.01 0.06 0.0405"/>
            </geometry>
            <material name="red"/>
        </visual>
        <visual>
            <origin xyz="0 0 0" rpy="0 0 ${pi/2}"/>
            <geometry>
                <box size="0.01 0.06 0.0405"/>
            </geometry>
            <material name="red"/>
        </visual>
        <visual>
            <origin xyz="0 0 0" rpy="0 0 ${-pi/4}"/>
            <geometry>
                <box size="0.01 0.06 0.0405"/>
            </geometry>
            <material name="red"/>
        </visual>
        <visual>
            <origin xyz="0 0 0" rpy="0 0 ${pi/4}"/>
            <geometry>
                <box size="0.01 0.06 0.0405"/>
            </geometry>
            <material name="red"/>
        </visual>
    </link>
    <gazebo reference="left_wheel_rim_link">
        <material>Gazebo/Red</material>
    </gazebo>


    <!--  ########################### -->



















    <!--  FRONT RIGHT WHEEL LINK -->

    <joint name="right_wheel_joint" type="continuous">
        <parent link="base_chassis_link"/>
        <child link="right_wheel_link"/>
        <origin xyz="0 -0.17 0" rpy="${-pi/2} 0 0"/>
        <axis xyz="0 0 1"/>
    </joint>


    <link name="right_wheel_link">
        <visual>
            <origin xyz="0 0 0" rpy="0 0 0"/>
            <geometry>
                <cylinder radius="0.05" length="0.04"/>
            </geometry>
            <material name="black"/>
        </visual>
        <collision>
           <origin xyz="0 0 0" rpy="0 0 0"/>
            <geometry>
                <sphere radius="0.05" />
            </geometry>
        </collision>
        <xacro:inertial_cylinder mass="0.5" length="0.04" radius="0.05">
            <origin xyz="0 0 0" rpy="0 0 0"/>
        </xacro:inertial_cylinder>
    </link>

    <gazebo reference="right_wheel_link">
        <mu1>1.0</mu1>
        <mu2>1.0</mu2>
        <!-- <kp>1000000.0</kp>
        <kd>1.0</kd>
        <fdir1>1 0 0</fdir1>
        <minDepth>0.1</minDepth> -->
        <material>Gazebo/FlatBlack</material>
    </gazebo>


    <joint name="right_wheel_rim_joint" type="fixed">
        <parent link="right_wheel_link"/>
        <child link="right_wheel_rim_link"/>
        <origin xyz="0 0 0" rpy="0 0 0"/>
    </joint>

    <link name="right_wheel_rim_link">
        <visual>
            <origin xyz="0 0 0" rpy="0 0 0"/>
            <geometry>
                <box size="0.01 0.06 0.0405"/>
            </geometry>
            <material name="red"/>
        </visual>
        <visual>
            <origin xyz="0 0 0" rpy="0 0 ${pi/2}"/>
            <geometry>
                <box size="0.01 0.06 0.0405"/>
            </geometry>
            <material name="red"/>
        </visual>
        <visual>
            <origin xyz="0 0 0" rpy="0 0 ${-pi/4}"/>
            <geometry>
                <box size="0.01 0.06 0.0405"/>
            </geometry>
            <material name="red"/>
        </visual>
        <visual>
            <origin xyz="0 0 0" rpy="0 0 ${pi/4}"/>
            <geometry>
                <box size="0.01 0.06 0.0405"/>
            </geometry>
            <material name="red"/>
        </visual>
    </link>
    <gazebo reference="right_wheel_rim_link">
        <material>Gazebo/Red</material>
    </gazebo>

    <!--  ########################### -->




















    <!--  CASTER WHEEL LINK -->

    <joint name="caster_wheel_joint" type="fixed">
        <parent link="base_chassis_link"/>
        <child link="caster_wheel_link"/>
        <origin xyz="-0.20 0 0"/>
    </joint>


    <link name="caster_wheel_link">
        <visual>
            <origin xyz="0 0 0" rpy="0 0 0"/>
            <geometry>
                <sphere radius="0.05" />
            </geometry>
            <material name="grey"/>
        </visual>
        <collision>
           <origin xyz="0 0 0" rpy="0 0 0"/>
            <geometry>
                <sphere radius="0.05" />
            </geometry>
        </collision>
        <xacro:inertial_sphere mass="0.2" radius="0.05">
            <origin xyz="0 0 0" rpy="0 0 0"/>
        </xacro:inertial_sphere>
    </link>

    <gazebo reference="caster_wheel_link">
        <mu1>0.001</mu1>
        <mu2>0.001</mu2>
        <!-- <kp>1000000.0</kp>
        <kd>1.0</kd>
        <fdir1>1 0 0</fdir1>
        <minDepth>0.1</minDepth> -->
        <material>Gazebo/Grey</material>
    </gazebo>

    <!--  ########################### -->






    <xacro:include filename="$(find mobo_bot_description)/urdf/ros_controllers.xacro"/>








    <xacro:include filename="$(find mobo_bot_description)/urdf/sensors/imu.xacro"/>
    <xacro:include filename="$(find mobo_bot_description)/urdf/sensors/lidar.xacro"/>
    <xacro:include filename="$(find mobo_bot_description)/urdf/sensors/cam.xacro"/>
    <xacro:include filename="$(find mobo_bot_description)/urdf/sensors/sonar.xacro"/>

  
</robot>